Workbook

Sheet Raw_Data
A1: CustomerID | B1: Age | C1: Gender | D1: Tenure_Months | E1: Balance | F1: NumOfProducts | G1: HasCrCard | H1: IsActiveMember | I1: EstimatedSalary | J1: Churn | K1: Duplicate_Check
A2: 1 | B2: 56 | C2: Male | D2: 40 | E2: 41393.42 | F2: 3 | G2: 1 | H2: 1 | I2: 101505.9 | J2: 0 | K2: =COUNTIF($A$2:$A$1001,A2) -> 1
A3: 2 | B3: 69 | C3: Male | D3: 45 | E3: 39385.65 | F3: 2 | G3: 1 | H3: 0 | I3: 125091.33 | J3: 0 | K3: =COUNTIF($A$2:$A$1001,A3) -> 1
A4: 3 | B4: 46 | C4: Male | D4: 62 | E4: 31221.27 | F4: 2 | G4: 0 | H4: 1 | I4: 99514.03 | J4: 0 | K4: =COUNTIF($A$2:$A$1001,A4) -> 1
A5: 4 | B5: 32 | C5: Female | D5: 58 | E5: 24724.06 | F5: 3 | G5: 0 | H5: 1 | I5: 58447.18 | J5: 0 | K5: =COUNTIF($A$2:$A$1001,A5) -> 1
A6: 5 | B6: 60 | C6: Male | D6: 67 | E6: 48977.54 | F6: 3 | G6: 1 | H6: 1 | I6: 53246.68 | J6: 0 | K6: =COUNTIF($A$2:$A$1001,A6) -> 1
A7: 6 | B7: 25 | C7: Male | D7: 56 | E7: 7248.25 | F7: 4 | G7: 0 | H7: 1 | I7: 62564.72 | J7: 0 | K7: =COUNTIF($A$2:$A$1001,A7) -> 1
A8: 7 | B8: 38 | C8: Male | D8: 40 | E8: 36257.79 | F8: 1 | G8: 0 | H8: 0 | I8: 41400.67 | J8: 0 | K8: =COUNTIF($A$2:$A$1001,A8) -> 1
A9: 8 | B9: 56 | C9: Female | D9: 40 | E9: 9559.54 | F9: 1 | G9: 1 | H9: 1 | I9: 43552.34 | J9: 0 | K9: =COUNTIF($A$2:$A$1001,A9) -> 1
A10: 9 | B10: 36 | C10: Female | D10: 33 | E10: 16913.16 | F10: 4 | G10: 0 | H10: 0 | I10: 122789.84 | J10: 0 | K10: =COUNTIF($A$2:$A$1001,A10) -> 1
A11: 10 | B11: 40 | C11: Male | D11: 6 | E11: 15434.94 | F11: 2 | G11: 1 | H11: 1 | I11: 70015.23 | J11: 0 | K11: =COUNTIF($A$2:$A$1001,A11) -> 1
A12: 11 | B12: 28 | C12: Male | D12: 19 | E12: 47351.8 | F12: 3 | G12: 1 | H12: 0 | I12: 76679.37 | J12: 0 | K12: =COUNTIF($A$2:$A$1001,A12) -> 1
A13: 12 | B13: 28 | C13: Male | D13: 40 | E13: 48367.81 | F13: 3 | G13: 1 | H13: 0 | I13: 97226.43 | J13: 0 | K13: =COUNTIF($A$2:$A$1001,A13) -> 1
... A1001: 1000 | B1001: 55 | C1001: Male | D1001: 42 | E1001: 33877.05 | F1001: 2 | G1001: 0 | H1001: 1 | I1001: 54522.49 | J1001: 0 | K1001: =COUNTIF($A$2:$A$1001,A1001) -> 1

Sheet Data_Cleaning_Log
A1: Check | B1: Column | C1: Result | D1: Action Taken
A2: Missing Values | B2: CustomerID | C2: =COUNTBLANK(Raw_Data!A2:A1001) -> 0 | D2: =IF(C2=0,"No action required","Investigate missing values") -> No action required
A3: Missing Values | B3: Age | C3: =COUNTBLANK(Raw_Data!B2:B1001) -> 0 | D3: =IF(C3=0,"No action required","Investigate missing values") -> No action required
A4: Missing Values | B4: Gender | C4: =COUNTBLANK(Raw_Data!C2:C1001) -> 0 | D4: =IF(C4=0,"No action required","Investigate missing values") -> No action required
A5: Missing Values | B5: Tenure_Months | C5: =COUNTBLANK(Raw_Data!D2:D1001) -> 0 | D5: =IF(C5=0,"No action required","Investigate missing values") -> No action required
A6: Missing Values | B6: Balance | C6: =COUNTBLANK(Raw_Data!E2:E1001) -> 0 | D6: =IF(C6=0,"No action required","Investigate missing values") -> No action required
A7: Missing Values | B7: NumOfProducts | C7: =COUNTBLANK(Raw_Data!F2:F1001) -> 0 | D7: =IF(C7=0,"No action required","Investigate missing values") -> No action required
A8: Missing Values | B8: HasCrCard | C8: =COUNTBLANK(Raw_Data!G2:G1001) -> 0 | D8: =IF(C8=0,"No action required","Investigate missing values") -> No action required
A9: Missing Values | B9: IsActiveMember | C9: =COUNTBLANK(Raw_Data!H2:H1001) -> 0 | D9: =IF(C9=0,"No action required","Investigate missing values") -> No action required
A10: Missing Values | B10: EstimatedSalary | C10: =COUNTBLANK(Raw_Data!I2:I1001) -> 0 | D10: =IF(C10=0,"No action required","Investigate missing values") -> No action required
A11: Missing Values | B11: Churn | C11: =COUNTBLANK(Raw_Data!J2:J1001) -> 0 | D11: =IF(C11=0,"No action required","Investigate missing values") -> No action required
A12: Duplicate Records | B12: CustomerID | C12: =COUNTIF(Raw_Data!K2:K1001,">1") -> 0 | D12: =IF(C12=0,"No duplicate CustomerIDs found","Investigate duplicate CustomerIDs") -> No duplicate CustomerIDs found
A13: Invalid Gender Values | B13: Gender | C13: =COUNTIFS(Raw_Data!C2:C1001,"<>Male",Raw_Data!C2:C1001,"<>Female",Raw_Data!C2:C1001,"<>") -> 0 | D13: =IF(C13=0,"No invalid values found","Investigate invalid gender values") -> No invalid values found
A14: Invalid Age Values | B14: Age | C14: =COUNTIF(Raw_Data!B2:B1001,"<=0") -> 0 | D14: =IF(C14=0,"No invalid values found","Investigate invalid age values") -> No invalid values found
A15: Invalid Tenure Values | B15: Tenure_Months | C15: =COUNTIF(Raw_Data!D2:D1001,"<0") -> 0 | D15: =IF(C15=0,"No invalid values found","Investigate invalid tenure values") -> No invalid values found
A16: Invalid Balance Values | B16: Balance | C16: =COUNTIF(Raw_Data!E2:E1001,"<0") -> 0 | D16: =IF(C16=0,"No invalid values found","Investigate invalid balance values") -> No invalid values found
A17: Invalid Credit Card Values | B17: HasCrCard | C17: =COUNTIFS(Raw_Data!G2:G1001,"<>0",Raw_Data!G2:G1001,"<>1",Raw_Data!G2:G1001,"<>") -> 0 | D17: =IF(C18=0,"No invalid values found","Investigate invalid credit card values") -> No invalid values found
A18: Invalid Active Member Values | B18: IsActiveMember | C18: =COUNTIFS(Raw_Data!H2:H1001,"<>0",Raw_Data!H2:H1001,"<>1",Raw_Data!H2:H1001,"<>") -> 0 | D18: =IF(C19=0,"No invalid values found","Investigate invalid active member values") -> No invalid values found
A19: Invalid Salary Values | B19: EstimatedSalary | C19: =COUNTIF(Raw_Data!I2:I1001,"<0") -> 0 | D19: =IF(C20=0,"No invalid values found","Investigate invalid salary values") -> No invalid values found
A20: Invalid Product Values | B20: NumOfProducts | C20: =COUNTIF(Raw_Data!F2:F1001,"<=0") -> 0 | D20: =IF(C17=0,"No invalid values found","Investigate invalid product values") -> No invalid values found
A21: Invalid Churn Values | B21: Churn | C21: =COUNTIFS(Raw_Data!J2:J1001,"<>0",Raw_Data!J2:J1001,"<>1",Raw_Data!J2:J1001,"<>") -> 0 | D21: =IF(C21=0,"No invalid values found","Investigate invalid churn values") -> No invalid values found
A22: Data Type Check | B22: CustomerID | C22: =COUNT(Raw_Data!A2:A1001) -> 1000 | D22: =IF(C23=1000,"Numeric - Valid","Check data type") -> Numeric - Valid
A23: Data Type Check | B23: Age | C23: =COUNT(Raw_Data!B2:B1001) -> 1000 | D23: =IF(C24=1000,"Numeric - Valid","Check data type") -> Numeric - Valid
A24: Data Type Check | B24: Gender | C24: =COUNTA(Raw_Data!C2:C1001) -> 1000 | D24: =IF(C25=1000,"Text/Categorical - Valid","Check data type") -> Text/Categorical - Valid
A25: Data Type Check | B25: Tenure_Months | C25: =COUNT(Raw_Data!D2:D1001) -> 1000 | D25: =IF(C26=1000,"Numeric - Valid","Check data type") -> Numeric - Valid
A26: Data Type Check | B26: Balance | C26: =COUNT(Raw_Data!E2:E1001) -> 1000 | D26: =IF(C27=1000,"Numeric - Valid","Check data type") -> Numeric - Valid
A27: Data Type Check | B27: NumOfProducts | C27: =COUNT(Raw_Data!F2:F1001) -> 1000 | D27: =IF(C28=1000,"Numeric - Valid","Check data type") -> Numeric - Valid
A28: Data Type Check | B28: HasCrCard | C28: =COUNT(Raw_Data!G2:G1001) -> 1000 | D28: =IF(C29=1000,"Numeric/Binary - Valid","Check data type") -> Numeric/Binary - Valid
A29: Data Type Check | B29: IsActiveMember | C29: =COUNT(Raw_Data!H2:H1001) -> 1000 | D29: =IF(C30=1000,"Numeric/Binary - Valid","Check data type") -> Numeric/Binary - Valid
A30: Data Type Check | B30: EstimatedSalary | C30: =COUNT(Raw_Data!I2:I1001) -> 1000 | D30: =IF(C31=1000,"Numeric - Valid","Check data type") -> Numeric - Valid
A31: Data Type Check | B31: Churn | C31: =COUNT(Raw_Data!J2:J1001) -> 1000 | D31: =IF(C31=1000,"Numeric/Binary - Valid","Check data type") -> Numeric/Binary - Valid
A32: Outlier Assessment | B32: Age | C32: 0 | D32: No IQR outliers; no action required
A33: Outlier Assessment | B33: Tenure_Months | C33: 0 | D33: No IQR outliers; no action required
A34: Outlier Assessment | B34: Balance | C34: 0 | D34: No IQR outliers; no action required
A35: Outlier Assessment | B35: EstimatedSalary | C35: 0 | D35: No IQR outliers; no action required
A36: Overall Data Quality Status | B36: All Checks | C36: Passed | D36: No missing, duplicate, invalid or IQR outlier records identified

Sheet Outlier_Analysis
A1: Variable | B1: Q1 | C1: Q3 | D1: IQR | E1: LOWER BOUND | F1: UPPER BOUND | G1: OUTLIER COUNT | H1: DECISION
A2: Age | B2: =_xlfn.QUARTILE.INC(Raw_Data!B2:B1001,1) -> 31 | C2: =_xlfn.QUARTILE.INC(Raw_Data!B2:B1001,3) -> 56 | D2: =C2-B2 -> 25 | E2: =B2-1.5*D2 -> -6.5 | F2: =C2+1.5*D2 -> 93.5 | G2: =COUNTIF(Raw_Data!B2:B1001,"<"&E2)+COUNTIF(Raw_Data!B2:B1001,">"&F2) -> 0 | H2: =IF(G2=0,"No IQR outliers","Outliers identified - investigate") -> No IQR outliers
A3: Tenure_Months | B3: =_xlfn.QUARTILE.INC(Raw_Data!D2:D1001,1) -> 17 | C3: =_xlfn.QUARTILE.INC(Raw_Data!D2:D1001,3) -> 52 | D3: =C3-B3 -> 35 | E3: =B3-1.5*D3 -> -35.5 | F3: =C3+1.5*D3 -> 104.5 | G3: =COUNTIF(Raw_Data!D2:D1001,"<"&E3)+COUNTIF(Raw_Data!D2:D1001,">"&F3) -> 0 | H3: =IF(G3=0,"No IQR outliers","Outliers identified - investigate") -> No IQR outliers
A4: Balance | B4: =_xlfn.QUARTILE.INC(Raw_Data!E2:E1001,1) -> 12678.458 | C4: =_xlfn.QUARTILE.INC(Raw_Data!E2:E1001,3) -> 37996.107 | D4: =C4-B4 -> 25317.65 | E4: =B4-1.5*D4 -> -25298.017 | F4: =C4+1.5*D4 -> 75972.582 | G4: =COUNTIF(Raw_Data!E2:E1001,"<"&E4)+COUNTIF(Raw_Data!E2:E1001,">"&F4) -> 0 | H4: =IF(G4=0,"No IQR outliers","Outliers identified - investigate") -> No IQR outliers
A5: EstimatedSalary | B5: =_xlfn.QUARTILE.INC(Raw_Data!I2:I1001,1) -> 51720.448 | C5: =_xlfn.QUARTILE.INC(Raw_Data!I2:I1001,3) -> 116665.86 | D5: =C5-B5 -> 64945.41 | E5: =B5-1.5*D5 -> -45697.668 | F5: =C5+1.5*D5 -> 214083.97 | G5: =COUNTIF(Raw_Data!I2:I1001,"<"&E5)+COUNTIF(Raw_Data!I2:I1001,">"&F5) -> 0 | H5: =IF(G5=0,"No IQR outliers","Outliers identified - investigate") -> No IQR outliers

Sheet Data_Dictionary
A1: Variable | B1: Description | C1: Data Type | D1: Measurement/Values | E1: Role
A2: CustomerID | B2: Unique identifier for each customer | C2: Numeric | D2: Unique ID | E2: Identifier
A3: Age | B3: Age of the customer | C3: Numeric | D3: Years | E3: Predictor
A4: Gender | B4: Gender of the customer | C4: Categorical | D4: Male/Female | E4: Predictor
A5: Tenure_Months | B5: Duration of customer relationship with the bank | C5: Numeric | D5: Months | E5: Predictor
A6: Balance | B6: Customer account balance | C6: Numeric | D6: Currency/amount | E6: Predictor
A7: NumOfProducts | B7: Number of banking products held | C7: Numeric | D7: Count | E7: Predictor
A8: HasCrCard | B8: Indicates whether customer has a credit card | C8: Binary | D8: 0/1 | E8: Predictor
A9: IsActiveMember | B9: Indicates whether customer is an active member | C9: Binary | D9: 0/1 | E9: Predictor
A10: EstimatedSalary | B10: Estimated customer salary | C10: Numeric | D10: Currency/amount | E10: Predictor
A11: Churn | B11: Indicates whether customer left the bank | C11: Binary | D11: 0 = No, 1 = Yes | E11: Target

Sheet Excel_Analysis
A1: CUSTOMER CHURN ANALYSIS
A3: KPI | B3: Value | D3: Churn Status | E3: Customers
A4: Total Customers | B4: =COUNTA(Raw_Data!A2:A1001) -> 1000 | D4: Retained | E4: =COUNTIF(Raw_Data!J2:J1001,0) -> 983
A5: Churned Customers | B5: =COUNTIF(Raw_Data!J2:J1001,1) -> 17 | D5: Churned | E5: =COUNTIF(Raw_Data!J2:J1001,1) -> 17
A6: Retained Customers | B6: =COUNTIF(Raw_Data!J2:J1001,0) -> 983
A7: Churn Rate | B7: =B5/B4 -> 0.017
A8: Retention Rate | B8: =B6/B4 -> 0.983 | D8: Gender | E8: Total Customers | F8: Churned Customers | G8: Churn Rate
D9: Male | E9: =COUNTIF(Raw_Data!C2:C1001,"Male") -> 524 | F9: =COUNTIFS(Raw_Data!C2:C1001,"Male",Raw_Data!J2:J1001,1) -> 7 | G9: =F9/E9 -> 0.013358779
A10: Column1 | B10: Column2 | D10: Female | E10: =COUNTIF(Raw_Data!C2:C1001,"Female") -> 476 | F10: =COUNTIFS(Raw_Data!C2:C1001,"Female",Raw_Data!J2:J1001,1) -> 10 | G10: =F10/E10 -> 0.021008403
A11: Average Age | B11: =AVERAGE(Raw_Data!B2:B1001) -> 43.819 | D11: Total | E11: =SUM(E9:E10) -> 1000 | F11: =SUM(F9:F10) -> 17 | G11: =F11/E11 -> 0.017
A12: Average Tenure (Months) | B12: =AVERAGE(Raw_Data!D2:D1001) -> 34.627
A13: Average Balance | B13: =AVERAGE(Raw_Data!E2:E1001) -> 25317.426
A14: Average Number of Products | B14: =AVERAGE(Raw_Data!F2:F1001) -> 2.485 | D14: Age Group | E14: Total Customers | F14: Churned Customers | G14: Churn Rate | H14: Interpretation
A15: Average Estimated Salary | B15: =AVERAGE(Raw_Data!I2:I1001) -> 83865.806 | D15: 18–25 | E15: =COUNTIFS(Raw_Data!B2:B1001,">=18",Raw_Data!B2:B1001,"<=25") -> 154 | F15: =COUNTIFS(Raw_Data!B2:B1001,">=18",Raw_Data!B2:B1001,"<=25",Raw_Data!J2:J1001,1) -> 4 | G15: =F15/E15 -> 0.025974026
D16: 26–35 | E16: =COUNTIFS(Raw_Data!B2:B1001,">=26",Raw_Data!B2:B1001,"<=35") -> 173 | F16: =COUNTIFS(Raw_Data!B2:B1001,">=26",Raw_Data!B2:B1001,"<=35",Raw_Data!J2:J1001,1) -> 1 | G16: =F16/E16 -> 0.0057803468
D17: 36–45 | E17: =COUNTIFS(Raw_Data!B2:B1001,">=36",Raw_Data!B2:B1001,"<=45") -> 208 | F17: =COUNTIFS(Raw_Data!B2:B1001,">=36",Raw_Data!B2:B1001,"<=45",Raw_Data!J2:J1001,1) -> 3 | G17: =F17/E17 -> 0.014423077
D18: 46–55 | E18: =COUNTIFS(Raw_Data!B2:B1001,">=46",Raw_Data!B2:B1001,"<=55") -> 201 | F18: =COUNTIFS(Raw_Data!B2:B1001,">=46",Raw_Data!B2:B1001,"<=55",Raw_Data!J2:J1001,1) -> 3 | G18: =F18/E18 -> 0.014925373
D19: 56+ | E19: =COUNTIF(Raw_Data!B2:B1001,">=56") -> 264 | F19: =COUNTIFS(Raw_Data!B2:B1001,">=56",Raw_Data!J2:J1001,1) -> 6 | G19: =F19/E19 -> 0.022727273
D20: Total | E20: =SUM(E15:E19) -> 1000 | F20: =SUM(F15:F19) -> 17 | G20: =F20/E20 -> 0.017
D23: Tenure Group | E23: Total Customers | F23: Churned Customers | G23: Churn Rate
D24: 0–12 | E24: =COUNTIFS(Raw_Data!D2:D1001,">=0",Raw_Data!D2:D1001,"<=12") -> 176 | F24: =COUNTIFS(Raw_Data!D2:D1001,">=0",Raw_Data!D2:D1001,"<=12",Raw_Data!J2:J1001,1) -> 17 | G24: =F24/E24 -> 0.096590909
D25: 13–24 | E25: =COUNTIFS(Raw_Data!D2:D1001,">=13",Raw_Data!D2:D1001,"<=24") -> 194 | F25: =COUNTIFS(Raw_Data!D2:D1001,">=13",Raw_Data!D2:D1001,"<=24",Raw_Data!J2:J1001,1) -> 0 | G25: =F25/E25 -> 0
D26: 25–36 | E26: =COUNTIFS(Raw_Data!D2:D1001,">=25",Raw_Data!D2:D1001,"<=36") -> 175 | F26: =COUNTIFS(Raw_Data!D2:D1001,">=25",Raw_Data!D2:D1001,"<=36",Raw_Data!J2:J1001,1) -> 0 | G26: =F26/E26 -> 0
D27: 37–48 | E27: =COUNTIFS(Raw_Data!D2:D1001,">=37",Raw_Data!D2:D1001,"<=48") -> 163 | F27: =COUNTIFS(Raw_Data!D2:D1001,">=37",Raw_Data!D2:D1001,"<=48",Raw_Data!J2:J1001,1) -> 0 | G27: =F27/E27 -> 0
D28: 49–60 | E28: =COUNTIFS(Raw_Data!D2:D1001,">=49",Raw_Data!D2:D1001,"<=60") -> 159 | F28: =COUNTIFS(Raw_Data!D2:D1001,">=49",Raw_Data!D2:D1001,"<=60",Raw_Data!J2:J1001,1) -> 0 | G28: =F28/E28 -> 0
D29: 61+ | E29: =COUNTIF(Raw_Data!D2:D1001,">=61") -> 133 | F29: =COUNTIFS(Raw_Data!D2:D1001,">=61",Raw_Data!J2:J1001,1) -> 0 | G29: =F29/E29 -> 0
D30: Total | E30: =SUM(E24:E29) -> 1000 | F30: =SUM(F24:F29) -> 17 | G30: =F30/E30 -> 0.017
D33: Number of Products | E33: Total Customers | F33: Churned Customers | G33: Churn Rate
D34: 1 | E34: =COUNTIF(Raw_Data!F2:F1001,1) -> 245 | F34: =COUNTIFS(Raw_Data!F2:F1001,1,Raw_Data!J2:J1001,1) -> 4 | G34: =F34/E34 -> 0.016326531
D35: 2 | E35: =COUNTIF(Raw_Data!F2:F1001,2) -> 259 | F35: =COUNTIFS(Raw_Data!F2:F1001,2,Raw_Data!J2:J1001,1) -> 2 | G35: =F35/E35 -> 0.0077220077
D36: 3 | E36: =COUNTIF(Raw_Data!F2:F1001,3) -> 262 | F36: =COUNTIFS(Raw_Data!F2:F1001,3,Raw_Data!J2:J1001,1) -> 2 | G36: =F36/E36 -> 0.0076335878
D37: 4 | E37: =COUNTIF(Raw_Data!F2:F1001,4) -> 234 | F37: =COUNTIFS(Raw_Data!F2:F1001,4,Raw_Data!J2:J1001,1) -> 9 | G37: =F37/E37 -> 0.038461538
D38: Total | E38: =SUM(E34:E37) -> 1000 | F38: =SUM(F34:F37) -> 17 | G38: =F38/E38 -> 0.017
D42: Active Member Status | E42: Total Customers | F42: Churned Customers | G42: Churn Rate
D43: Inactive | E43: =COUNTIF(Raw_Data!H2:H1001,0) -> 500 | F43: =COUNTIFS(Raw_Data!H2:H1001,0,Raw_Data!J2:J1001,1) -> 17 | G43: =F43/E43 -> 0.034
D44: Active | E44: =COUNTIF(Raw_Data!H2:H1001,1) -> 500 | F44: =COUNTIFS(Raw_Data!H2:H1001,1,Raw_Data!J2:J1001,1) -> 0 | G44: =F44/E44 -> 0
D45: Total | E45: =SUM(E43:E44) -> 1000 | F45: =SUM(F43:F44) -> 17 | G45: =F45/E45 -> 0.017
D48: Credit Card Status | E48: Total Customers | F48: Churned Customers | G48: Churn Rate
D49: No Credit Card | E49: =COUNTIF(Raw_Data!G2:G1001,0) -> 493 | F49: =COUNTIFS(Raw_Data!G2:G1001,0,Raw_Data!J2:J1001,1) -> 6 | G49: =F49/E49 -> 0.012170385
D50: Has Credit Card | E50: =COUNTIF(Raw_Data!G2:G1001,1) -> 507 | F50: =COUNTIFS(Raw_Data!G2:G1001,1,Raw_Data!J2:J1001,1) -> 11 | G50: =F50/E50 -> 0.021696252
...

Sheet Risk_Segmentation
A1: CustomerID | B1: Age | C1: Tenure | D1: Products | E1: Active Member | F1: Credit Card | G1: Balance | H1: Salary | I1: Churn | J1: Risk Score | K1: Risk Level | M1: Risk Level | N1: Customers | O1: Churned Customers | P1: Churn Rate
A2: =Raw_Data!A2 -> 1 | B2: =Raw_Data!B2 -> 56 | C2: =Raw_Data!D2 -> 40 | D2: =Raw_Data!F2 -> 3 | E2: =Raw_Data!H2 -> 1 | F2: =Raw_Data!G2 -> 1 | G2: =Raw_Data!E2 -> 41393.42 | H2: =Raw_Data!I2 -> 101505.9 | I2: =Raw_Data!J2 -> 0 | J2: =IF(E2=0,2,0)+IF(D2=4,2,0)+IF(C2<=12,2,0)+IF(B2>=56,1,0)+IF(G2>=40000,1,0) -> 2 | K2: =IF(J2>=5,"High Risk",IF(J2>=3,"Medium Risk","Low Risk")) -> Low Risk | M2: Low Risk | N2: =COUNTIF(K2:K1001,"Low Risk") -> 603 | O2: =COUNTIFS(K2:K1001,"Low Risk",I2:I1001,1) -> 0 | P2: =O2/N2 -> 0
A3: =Raw_Data!A3 -> 2 | B3: =Raw_Data!B3 -> 69 | C3: =Raw_Data!D3 -> 45 | D3: =Raw_Data!F3 -> 2 | E3: =Raw_Data!H3 -> 0 | F3: =Raw_Data!G3 -> 1 | G3: =Raw_Data!E3 -> 39385.65 | H3: =Raw_Data!I3 -> 125091.33 | I3: =Raw_Data!J3 -> 0 | J3: =IF(E3=0,2,0)+IF(D3=4,2,0)+IF(C3<=12,2,0)+IF(B3>=56,1,0)+IF(G3>=40000,1,0) -> 3 | K3: =IF(J3>=5,"High Risk",IF(J3>=3,"Medium Risk","Low Risk")) -> Medium Risk | M3: Medium Risk | N3: =COUNTIF(K2:K1001,"Medium Risk") -> 296 | O3: =COUNTIFS(K3:K1002,"Medium Risk",I3:I1002,1) -> 7 | P3: =O3/N3 -> 0.023648649
A4: =Raw_Data!A4 -> 3 | B4: =Raw_Data!B4 -> 46 | C4: =Raw_Data!D4 -> 62 | D4: =Raw_Data!F4 -> 2 | E4: =Raw_Data!H4 -> 1 | F4: =Raw_Data!G4 -> 0 | G4: =Raw_Data!E4 -> 31221.27 | H4: =Raw_Data!I4 -> 99514.03 | I4: =Raw_Data!J4 -> 0 | J4: =IF(E4=0,2,0)+IF(D4=4,2,0)+IF(C4<=12,2,0)+IF(B4>=56,1,0)+IF(G4>=40000,1,0) -> 0 | K4: =IF(J4>=5,"High Risk",IF(J4>=3,"Medium Risk","Low Risk")) -> Low Risk | M4: High Risk | N4: =COUNTIF(K2:K1001,"High Risk") -> 101 | O4: =COUNTIFS(K4:K1003,"High Risk",I4:I1003,1) -> 10 | P4: =O4/N4 -> 0.099009901
A5: =Raw_Data!A5 -> 4 | B5: =Raw_Data!B5 -> 32 | C5: =Raw_Data!D5 -> 58 | D5: =Raw_Data!F5 -> 3 | E5: =Raw_Data!H5 -> 1 | F5: =Raw_Data!G5 -> 0 | G5: =Raw_Data!E5 -> 24724.06 | H5: =Raw_Data!I5 -> 58447.18 | I5: =Raw_Data!J5 -> 0 | J5: =IF(E5=0,2,0)+IF(D5=4,2,0)+IF(C5<=12,2,0)+IF(B5>=56,1,0)+IF(G5>=40000,1,0) -> 0 | K5: =IF(J5>=5,"High Risk",IF(J5>=3,"Medium Risk","Low Risk")) -> Low Risk | M5: Total | N5: =SUM(N2:N4) -> 1000 | O5: =SUM(O2:O4) -> 17 | P5: =O5/N5 -> 0.017
A6: =Raw_Data!A6 -> 5 | B6: =Raw_Data!B6 -> 60 | C6: =Raw_Data!D6 -> 67 | D6: =Raw_Data!F6 -> 3 | E6: =Raw_Data!H6 -> 1 | F6: =Raw_Data!G6 -> 1 | G6: =Raw_Data!E6 -> 48977.54 | H6: =Raw_Data!I6 -> 53246.68 | I6: =Raw_Data!J6 -> 0 | J6: =IF(E6=0,2,0)+IF(D6=4,2,0)+IF(C6<=12,2,0)+IF(B6>=56,1,0)+IF(G6>=40000,1,0) -> 2 | K6: =IF(J6>=5,"High Risk",IF(J6>=3,"Medium Risk","Low Risk")) -> Low Risk
A7: =Raw_Data!A7 -> 6 | B7: =Raw_Data!B7 -> 25 | C7: =Raw_Data!D7 -> 56 | D7: =Raw_Data!F7 -> 4 | E7: =Raw_Data!H7 -> 1 | F7: =Raw_Data!G7 -> 0 | G7: =Raw_Data!E7 -> 7248.25 | H7: =Raw_Data!I7 -> 62564.72 | I7: =Raw_Data!J7 -> 0 | J7: =IF(E7=0,2,0)+IF(D7=4,2,0)+IF(C7<=12,2,0)+IF(B7>=56,1,0)+IF(G7>=40000,1,0) -> 2 | K7: =IF(J7>=5,"High Risk",IF(J7>=3,"Medium Risk","Low Risk")) -> Low Risk
A8: =Raw_Data!A8 -> 7 | B8: =Raw_Data!B8 -> 38 | C8: =Raw_Data!D8 -> 40 | D8: =Raw_Data!F8 -> 1 | E8: =Raw_Data!H8 -> 0 | F8: =Raw_Data!G8 -> 0 | G8: =Raw_Data!E8 -> 36257.79 | H8: =Raw_Data!I8 -> 41400.67 | I8: =Raw_Data!J8 -> 0 | J8: =IF(E8=0,2,0)+IF(D8=4,2,0)+IF(C8<=12,2,0)+IF(B8>=56,1,0)+IF(G8>=40000,1,0) -> 2 | K8: =IF(J8>=5,"High Risk",IF(J8>=3,"Medium Risk","Low Risk")) -> Low Risk | M8: Key Finding
A9: =Raw_Data!A9 -> 8 | B9: =Raw_Data!B9 -> 56 | C9: =Raw_Data!D9 -> 40 | D9: =Raw_Data!F9 -> 1 | E9: =Raw_Data!H9 -> 1 | F9: =Raw_Data!G9 -> 1 | G9: =Raw_Data!E9 -> 9559.54 | H9: =Raw_Data!I9 -> 43552.34 | I9: =Raw_Data!J9 -> 0 | J9: =IF(E9=0,2,0)+IF(D9=4,2,0)+IF(C9<=12,2,0)+IF(B9>=56,1,0)+IF(G9>=40000,1,0) -> 1 | K9: =IF(J9>=5,"High Risk",IF(J9>=3,"Medium Risk","Low Risk")) -> Low Risk | M9: High-risk customers have the highest observed churn rate of 9.90%.
A10: =Raw_Data!A10 -> 9 | B10: =Raw_Data!B10 -> 36 | C10: =Raw_Data!D10 -> 33 | D10: =Raw_Data!F10 -> 4 | E10: =Raw_Data!H10 -> 0 | F10: =Raw_Data!G10 -> 0 | G10: =Raw_Data!E10 -> 16913.16 | H10: =Raw_Data!I10 -> 122789.84 | I10: =Raw_Data!J10 -> 0 | J10: =IF(E10=0,2,0)+IF(D10=4,2,0)+IF(C10<=12,2,0)+IF(B10>=56,1,0)+IF(G10>=40000,1,0) -> 4 | K10: =IF(J10>=5,"High Risk",IF(J10>=3,"Medium Risk","Low Risk")) -> Medium Risk | M10: Medium-risk customers have a churn rate of 2.36%.
A11: =Raw_Data!A11 -> 10 | B11: =Raw_Data!B11 -> 40 | C11: =Raw_Data!D11 -> 6 | D11: =Raw_Data!F11 -> 2 | E11: =Raw_Data!H11 -> 1 | F11: =Raw_Data!G11 -> 1 | G11: =Raw_Data!E11 -> 15434.94 | H11: =Raw_Data!I11 -> 70015.23 | I11: =Raw_Data!J11 -> 0 | J11: =IF(E11=0,2,0)+IF(D11=4,2,0)+IF(C11<=12,2,0)+IF(B11>=56,1,0)+IF(G11>=40000,1,0) -> 2 | K11: =IF(J11>=5,"High Risk",IF(J11>=3,"Medium Risk","Low Risk")) -> Low Risk | M11: No churn was observed among low-risk customers in this dataset.
A12: =Raw_Data!A12 -> 11 | B12: =Raw_Data!B12 -> 28 | C12: =Raw_Data!D12 -> 19 | D12: =Raw_Data!F12 -> 3 | E12: =Raw_Data!H12 -> 0 | F12: =Raw_Data!G12 -> 1 | G12: =Raw_Data!E12 -> 47351.8 | H12: =Raw_Data!I12 -> 76679.37 | I12: =Raw_Data!J12 -> 0 | J12: =IF(E12=0,2,0)+IF(D12=4,2,0)+IF(C12<=12,2,0)+IF(B12>=56,1,0)+IF(G12>=40000,1,0) -> 3 | K12: =IF(J12>=5,"High Risk",IF(J12>=3,"Medium Risk","Low Risk")) -> Medium Risk | M12: Risk segmentation indicates a clear difference in observed churn across the three groups.
A13: =Raw_Data!A13 -> 12 | B13: =Raw_Data!B13 -> 28 | C13: =Raw_Data!D13 -> 40 | D13: =Raw_Data!F13 -> 3 | E13: =Raw_Data!H13 -> 0 | F13: =Raw_Data!G13 -> 1 | G13: =Raw_Data!E13 -> 48367.81 | H13: =Raw_Data!I13 -> 97226.43 | I13: =Raw_Data!J13 -> 0 | J13: =IF(E13=0,2,0)+IF(D13=4,2,0)+IF(C13<=12,2,0)+IF(B13>=56,1,0)+IF(G13>=40000,1,0) -> 3 | K13: =IF(J13>=5,"High Risk",IF(J13>=3,"Medium Risk","Low Risk")) -> Medium Risk
A14: =Raw_Data!A14 -> 13 | B14: =Raw_Data!B14 -> 41 | C14: =Raw_Data!D14 -> 59 | D14: =Raw_Data!F14 -> 3 | E14: =Raw_Data!H14 -> 1 | F14: =Raw_Data!G14 -> 1 | G14: =Raw_Data!E14 -> 9150.77 | H14: =Raw_Data!I14 -> 96654.95 | I14: =Raw_Data!J14 -> 0 | J14: =IF(E14=0,2,0)+IF(D14=4,2,0)+IF(C14<=12,2,0)+IF(B14>=56,1,0)+IF(G14>=40000,1,0) -> 0 | K14: =IF(J14>=5,"High Risk",IF(J14>=3,"Medium Risk","Low Risk")) -> Low Risk
A15: =Raw_Data!A15 -> 14 | B15: =Raw_Data!B15 -> 53 | C15: =Raw_Data!D15 -> 59 | D15: =Raw_Data!F15 -> 2 | E15: =Raw_Data!H15 -> 1 | F15: =Raw_Data!G15 -> 1 | G15: =Raw_Data!E15 -> 1101.76 | H15: =Raw_Data!I15 -> 28758.99 | I15: =Raw_Data!J15 -> 0 | J15: =IF(E15=0,2,0)+IF(D15=4,2,0)+IF(C15<=12,2,0)+IF(B15>=56,1,0)+IF(G15>=40000,1,0) -> 0 | K15: =IF(J15>=5,"High Risk",IF(J15>=3,"Medium Risk","Low Risk")) -> Low Risk
A16: =Raw_Data!A16 -> 15 | B16: =Raw_Data!B16 -> 57 | C16: =Raw_Data!D16 -> 48 | D16: =Raw_Data!F16 -> 3 | E16: =Raw_Data!H16 -> 1 | F16: =Raw_Data!G16 -> 0 | G16: =Raw_Data!E16 -> 36000.4 | H16: =Raw_Data!I16 -> 128100.3 | I16: =Raw_Data!J16 -> 0 | J16: =IF(E16=0,2,0)+IF(D16=4,2,0)+IF(C16<=12,2,0)+IF(B16>=56,1,0)+IF(G16>=40000,1,0) -> 1 | K16: =IF(J16>=5,"High Risk",IF(J16>=3,"Medium Risk","Low Risk")) -> Low Risk
A17: =Raw_Data!A17 -> 16 | B17: =Raw_Data!B17 -> 41 | C17: =Raw_Data!D17 -> 41 | D17: =Raw_Data!F17 -> 3 | E17: =Raw_Data!H17 -> 0 | F17: =Raw_Data!G17 -> 1 | G17: =Raw_Data!E17 -> 20899.5 | H17: =Raw_Data!I17 -> 43052.45 | I17: =Raw_Data!J17 -> 0 | J17: =IF(E17=0,2,0)+IF(D17=4,2,0)+IF(C17<=12,2,0)+IF(B17>=56,1,0)+IF(G17>=40000,1,0) -> 2 | K17: =IF(J17>=5,"High Risk",IF(J17>=3,"Medium Risk","Low Risk")) -> Low Risk
A18: =Raw_Data!A18 -> 17 | B18: =Raw_Data!B18 -> 20 | C18: =Raw_Data!D18 -> 13 | D18: =Raw_Data!F18 -> 4 | E18: =Raw_Data!H18 -> 1 | F18: =Raw_Data!G18 -> 0 | G18: =Raw_Data!E18 -> 4442.01 | H18: =Raw_Data!I18 -> 113999.31 | I18: =Raw_Data!J18 -> 0 | J18: =IF(E18=0,2,0)+IF(D18=4,2,0)+IF(C18<=12,2,0)+IF(B18>=56,1,0)+IF(G18>=40000,1,0) -> 2 | K18: =IF(J18>=5,"High Risk",IF(J18>=3,"Medium Risk","Low Risk")) -> Low Risk
A19: =Raw_Data!A19 -> 18 | B19: =Raw_Data!B19 -> 39 | C19: =Raw_Data!D19 -> 45 | D19: =Raw_Data!F19 -> 2 | E19: =Raw_Data!H19 -> 1 | F19: =Raw_Data!G19 -> 1 | G19: =Raw_Data!E19 -> 34187.71 | H19: =Raw_Data!I19 -> 120447.23 | I19: =Raw_Data!J19 -> 0 | J19: =IF(E19=0,2,0)+IF(D19=4,2,0)+IF(C19<=12,2,0)+IF(B19>=56,1,0)+IF(G19>=40000,1,0) -> 0 | K19: =IF(J19>=5,"High Risk",IF(J19>=3,"Medium Risk","Low Risk")) -> Low Risk
A20: =Raw_Data!A20 -> 19 | B20: =Raw_Data!B20 -> 19 | C20: =Raw_Data!D20 -> 53 | D20: =Raw_Data!F20 -> 1 | E20: =Raw_Data!H20 -> 0 | F20: =Raw_Data!G20 -> 1 | G20: =Raw_Data!E20 -> 27255.28 | H20: =Raw_Data!I20 -> 112936.94 | I20: =Raw_Data!J20 -> 0 | J20: =IF(E20=0,2,0)+IF(D20=4,2,0)+IF(C20<=12,2,0)+IF(B20>=56,1,0)+IF(G20>=40000,1,0) -> 2 | K20: =IF(J20>=5,"High Risk",IF(J20>=3,"Medium Risk","Low Risk")) -> Low Risk
A21: =Raw_Data!A21 -> 20 | B21: =Raw_Data!B21 -> 41 | C21: =Raw_Data!D21 -> 42 | D21: =Raw_Data!F21 -> 4 | E21: =Raw_Data!H21 -> 1 | F21: =Raw_Data!G21 -> 1 | G21: =Raw_Data!E21 -> 49025.84 | H21: =Raw_Data!I21 -> 95267.09 | I21: =Raw_Data!J21 -> 0 | J21: =IF(E21=0,2,0)+IF(D21=4,2,0)+IF(C21<=12,2,0)+IF(B21>=56,1,0)+IF(G21>=40000,1,0) -> 3 | K21: =IF(J21>=5,"High Risk",IF(J21>=3,"Medium Risk","Low Risk")) -> Medium Risk
A22: =Raw_Data!A22 -> 21 | B22: =Raw_Data!B22 -> 61 | C22: =Raw_Data!D22 -> 63 | D22: =Raw_Data!F22 -> 4 | E22: =Raw_Data!H22 -> 0 | F22: =Raw_Data!G22 -> 0 | G22: =Raw_Data!E22 -> 11370.47 | H22: =Raw_Data!I22 -> 21899.17 | I22: =Raw_Data!J22 -> 0 | J22: =IF(E22=0,2,0)+IF(D22=4,2,0)+IF(C22<=12,2,0)+IF(B22>=56,1,0)+IF(G22>=40000,1,0) -> 5 | K22: =IF(J22>=5,"High Risk",IF(J22>=3,"Medium Risk","Low Risk")) -> High Risk
A23: =Raw_Data!A23 -> 22 | B23: =Raw_Data!B23 -> 47 | C23: =Raw_Data!D23 -> 27 | D23: =Raw_Data!F23 -> 1 | E23: =Raw_Data!H23 -> 1 | F23: =Raw_Data!G23 -> 1 | G23: =Raw_Data!E23 -> 20198.89 | H23: =Raw_Data!I23 -> 66848.81 | I23: =Raw_Data!J23 -> 0 | J23: =IF(E23=0,2,0)+IF(D23=4,2,0)+IF(C23<=12,2,0)+IF(B23>=56,1,0)+IF(G23>=40000,1,0) -> 0 | K23: =IF(J23>=5,"High Risk",IF(J23>=3,"Medium Risk","Low Risk")) -> Low Risk
A24: =Raw_Data!A24 -> 23 | B24: =Raw_Data!B24 -> 55 | C24: =Raw_Data!D24 -> 38 | D24: =Raw_Data!F24 -> 4 | E24: =Raw_Data!H24 -> 0 | F24: =Raw_Data!G24 -> 1 | G24: =Raw_Data!E24 -> 27127.29 | H24: =Raw_Data!I24 -> 98629.13 | I24: =Raw_Data!J24 -> 0 | J24: =IF(E24=0,2,0)+IF(D24=4,2,0)+IF(C24<=12,2,0)+IF(B24>=56,1,0)+IF(G24>=40000,1,0) -> 4 | K24: =IF(J24>=5,"High Risk",IF(J24>=3,"Medium Risk","Low Risk")) -> Medium Risk
... A1001: =Raw_Data!A1001 -> 1000 | B1001: =Raw_Data!B1001 -> 55 | C1001: =Raw_Data!D1001 -> 42 | D1001: =Raw_Data!F1001 -> 2 | E1001: =Raw_Data!H1001 -> 1 | F1001: =Raw_Data!G1001 -> 0 | G1001: =Raw_Data!E1001 -> 33877.05 | H1001: =Raw_Data!I1001 -> 54522.49 | I1001: =Raw_Data!J1001 -> 0 | J1001: =IF(E1001=0,2,0)+IF(D1001=4,2,0)+IF(C1001<=12,2,0)+IF(B1001>=56,1,0)+IF(G1001>=40000,1,0) -> 0 | K1001: =IF(J1001>=5,"High Risk",IF(J1001>=3,"Medium Risk","Low Risk")) -> Low Risk

Sheet Hypothesis_Testing
A1: Active Membership vs Churn
A2: Status | B2: Not Churned | C2: Churned
A3: Inactive | B3: =COUNTIFS(Raw_Data!H2:H1001,0,Raw_Data!J2:J1001,0) -> 483 | C3: =COUNTIFS(Raw_Data!H2:H1001,0,Raw_Data!J2:J1001,1) -> 17
A4: Active | B4: =COUNTIFS(Raw_Data!H2:H1001,1,Raw_Data!J2:J1001,0) -> 500 | C4: =COUNTIFS(Raw_Data!H2:H1001,1,Raw_Data!J2:J1001,1) -> 0
A7: Number of Products vs Churn
A8: Products | B8: Not Churned | C8: Churned
A9: 1 | B9: =COUNTIFS(Raw_Data!F2:F1001,1,Raw_Data!J2:J1001,0) -> 241 | C9: =COUNTIFS(Raw_Data!F2:F1001,1,Raw_Data!J2:J1001,1) -> 4
A10: 2 | B10: =COUNTIFS(Raw_Data!F2:F1001,2,Raw_Data!J2:J1001,0) -> 257 | C10: =COUNTIFS(Raw_Data!F2:F1001,2,Raw_Data!J2:J1001,1) -> 2
A11: 3 | B11: =COUNTIFS(Raw_Data!F2:F1001,3,Raw_Data!J2:J1001,0) -> 260 | C11: =COUNTIFS(Raw_Data!F2:F1001,3,Raw_Data!J2:J1001,1) -> 2
A12: 4 | B12: =COUNTIFS(Raw_Data!F2:F1001,4,Raw_Data!J2:J1001,0) -> 225 | C12: =COUNTIFS(Raw_Data!F2:F1001,4,Raw_Data!J2:J1001,1) -> 9
A13: Total | B13: =SUM(B9:B12) -> 983 | C13: =SUM(C9:C12) -> 17
A15: Hypothesis 2 | B15: Number of Products and Customer Churn
A16: H0 (Null Hypothesis) | B16: Number of products held by a customer has no significant relationship with customer churn.
A17: H1 (Alternative Hypothesis) | B17: Number of products held by a customer has a significant relationship with customer churn.
A18: Observation | B18: Customers holding 4 products show the highest churn count.
A21: Chi-Square Test: Number of Products vs Churn
A22: Products | B22: Not Churned | C22: Churned | D22: Total | F22: Products | G22: Not Churned | H22: Churned
A23: 1 | B23: 241 | C23: 4 | D23: =SUM(B23:C23) -> 245 | F23: 1 | G23: =D23*$B$27/$D$27 -> 240.835 | H23: =D23*$C$27/$D$27 -> 4.165
A24: 2 | B24: 257 | C24: 2 | D24: =SUM(B24:C24) -> 259 | F24: 2 | G24: =D24*$B$27/$D$27 -> 254.597 | H24: =D24*$C$27/$D$27 -> 4.403
A25: 3 | B25: 260 | C25: 2 | D25: =SUM(B25:C25) -> 262 | F25: 3 | G25: =D25*$B$27/$D$27 -> 257.546 | H25: =D25*$C$27/$D$27 -> 4.454
A26: 4 | B26: 225 | C26: 9 | D26: =SUM(B26:C26) -> 234 | F26: 4 | G26: =D26*$B$27/$D$27 -> 230.022 | H26: =D26*$C$27/$D$27 -> 3.978
A27: Total | B27: 983 | C27: 17 | D27: =SUM(B27:C27) -> 1000 | F27: Total | G27: =D27*$B$27/$D$27 -> 983 | H27: =D27*$C$27/$D$27 -> 17
F29: Chi-Square Statistic | G29: {=SUMPRODUCT((B23:C26-G23:H26)^2/(G23:H26))} -> 9.1658883
F30: p-value | G30: =_xlfn.CHISQ.TEST(B23:C26,G23:H26) -> 0.027164714
F31: Significance Level | G31: 0.05
F32: Decision | G32: =IF(G30<0.05,"Reject H0","Fail to Reject H0") -> Reject H0
F33: Conclusion | G33: There is a statistically significant relationship between the number of products held by customers and customer churn.
F34: Business Insight | G34: Customers with 4 products have the highest observed churn count and should be investigated for retention strategies.
A36: Hypothesis 1 | B36: Active Membership and Customer Churn
A37: H0 (Null Hypothesis) | B37: Active membership status has no significant relationship with customer churn.
A38: H1 (Alternative Hypothesis) | B38: Active membership status has a significant relationship with customer churn.
A39: Observation | B39: All observed churned customers belong to the inactive membership group.
A42: Status | B42: Not Churned | C42: Churned | D42: Total | F42: Status | G42: Expected Not Churned | H42: Expected Churned
A43: Inactive | B43: 483 | C43: 17 | D43: =SUM(B43:C43) -> 500 | F43: Inactive | G43: =D43*$B$45/$D$45 -> 491.5 | H43: =D43*$C$45/$D$45 -> 8.5
A44: Active | B44: 500 | C44: 0 | D44: =SUM(B44:C44) -> 500 | F44: Active | G44: =D44*$B$45/$D$45 -> 491.5 | H44: =D44*$C$45/$D$45 -> 8.5
A45: Total | B45: 983 | C45: 17 | D45: =SUM(B45:C45) -> 1000 | F45: Total | G45: =SUM(G43:G44) -> 983 | H45: =D45*$C$45/$D$45 -> 17
F47: Chi-Square Statistic | G47: {=SUMPRODUCT((B43:C44-G43:H44)^2/(G43:H44))} -> 17.293998
F48: p-value | G48: =_xlfn.CHISQ.TEST(B43:C44,G43:H44) -> 3.2019663e-05
F49: Significance Level | G49: 0.05
F50: Decision | G50: =IF(G48<0.05,"Reject H0","Fail to Reject H0") -> Reject H0
...
